Workbook

Sheet BS I A
A5: N° | B5: N° DE INSCRIPCIÓN | C5: ACTO RESOLUTIVO | D5: FECHA DE RD (DIA/MES/AÑO) | E5: FECHA DE PUBLICACION RD | F5: RENIPRESS | G5: CATEGORIA | H5: DIRESA/GERESA | I5: IPRESS | J5: DISTRITO | K5: PROVINCIA | L5: REGION | M5: DIRECCIÓN | N5: SUBSECTOR | O5: DIRECTOR | P5: CONTACTO | Q5: JEFE DE BANCO DE SANGRE | R5: CONTACTO | S5: Personal | T5: Patólogo Clínico | U5: Otras Especial | V5: T.M. | W5: Biol. | X5: N° EXPEDIENTES | Y5: CONVENIO | Z5: MODIFICACIÓN EN RECURSOS HUMANOS, INFRAESTRUCTURA, EQUIPAMIENTO, CONVENIOS, ETC.
A6: 1 | B6: PER-BSIA150114-001 | C6: R.D. N° 002-2022 DIGDOT/MINSA | D6: 44874 | E6: 44909 | F6: 22113 | G6: II-E | H6: DIRIS LIMA ESTE | I6: CLÍNICA SANTA JULIA | J6: LA MOLINA | K6: LIMA | L6: LIMA | M6: AV. JAVIER PRADO N° 7118 | N6: PRIVADO | O6: Dr. OSCAR ALBERTO ALVARADO GALINDO | P6: oscaralvarado44@yahoo.es | Q6: Médico Patólogo Clínico Reynaldo Giovanni Estela Ramírez | R6: Cel: 996228972 correo: Reyesra98@yahoo.com | S6: Médico Patólogo Clínico Reynaldo Giovanni Estela Ramírez, T.M. Santos Juan Auqui Sulca, T.M. Jorge Antonio Vásquez Epequin | T6: 1 | U6: 0 | V6: 2 | W6: 0 | X6: N° 2022-0042252, N° 2022-0048706 | Y6: POR REGULARIZAR | AB6: PRIVADO | AC6: =COUNTIF($N$6:$N$595,"PRIVADO") -> 236
A7: 2 | B7: PER-BSIA150117-002 | C7: R.D. N° 003-2022 DIGDOT/MINSA | D7: 44874 | E7: 44909 | F7: 9641 | G7: II-E | H7: DIRIS LIMA NORTE | I7: CLÍNICA MUNDO SALUD | J7: LOS OLIVOS | K7: LIMA | L7: LIMA | M7: AV. CARLOS IZAGUIRRE N° 1234 | N7: PRIVADO | O7: Dra. MONICA BEATRIZ ALFONSO SALAS | P7: Cel: 989011384 - 942474041 | Q7: Médico Patólogo Clínico Wilder Eduardo Ramos Castillo | R7: Cel: 971500688 correo: willy.erc2308@gmail.com | S7: TM. Roxana Valer Vilcahuaman, TM. Miriam Loayza Yasonna, TM Milena Chavez | T7: 1 | U7: 0 | V7: 3 | W7: 0 | X7: N° 2022-0040639, N° DIGDOT20220000376 | Y7: POR REGULARIZAR | Z7: comunica horario de atencion de 8am a 8pm | AB7: MINSA | AC7: =COUNTIF($N$6:$N$596,"MINSA") -> 48
A8: 3 | B8: PER-BSIA150130-003 | C8: R.D. N° 004-2022 DIGDOT/MINSA R.D. N.° 016-2025-DIGDOT-MINSA | D8: 9/11/2022 28/02/2025 | E8: 14/12/2022 28/02/2025 | F8: 33189 | H8: DIRIS LIMA CENTRO | I8: CLÍNICA INSTITUTO ONCOLÓGICO PERUANO S.A.C. (SUSPENSION DEFINITIVA) | J8: SAN BORJA | K8: LIMA | M8: JR. EDUARDO ORDOÑEZ N° 215 | O8: Dr. GERARDO JIMMY CAMPOS SICCHA | P8: Cel: 993061742 | Q8: Médico especialista en Patología y Laboratorio Clínico Cesar Augusto Chian García | R8: Cel: 990380377 correo: cesar.chian@upch.pe | S8: Médico en Patología y Lab. Clínico Cesar Augusto Chian García, Médico Hematóloga Melissa Caterina Morales Coloma, T.M. Rosa Elena Chumpitaz Arias, T.M. Ángel Satoshi Villegas Pérez, T.M. Jaime Eberto Carrión Basauri, Téc. Lab. Víctor Miguel Vásquez Robles | T8: 0 | U8: 2 | V8: 3 | W8: 0 | X8: N° 2022-0051539, N° 2022-0039799 | Y8: POR REGULARIZAR | AB8: ESSALUD | AC8: =COUNTIF($N$6:$N$597,"ESSALUD") -> 22
A9: 4 | B9: PER-BSIA040129-004 | C9: R.D. N° 005-2022 DIGDOT/MINSA | D9: 44874 | E9: 44999 | F9: 24554 | G9: II-E | H9: GERESA AREQUIPA | I9: CLÍNICA UROSUR | J9: JOSÉ LUIS BUSTAMANTE Y RIVERO | K9: AREQUIPA | L9: AREQUIPA | M9: URN. LA ESPERANZA E-6 | N9: PRIVADO | O9: Dra. ROXANA PONCE QUISPE | P9: 054 - 423738 | Q9: Médica Patóloga Clínica Gleidy Mallma Vilca | R9: Cel: 974218956 correo: gleidy432@gmail.com | S9: Médica Patóloga Clínica Gleidy Mallma Vilca, T.M. Milagros Del Rosario Chávez, T.M. Obdulia Jenne Ortiz Astorga, Bióloga Erika Gladiz Ninahuaman Aracayo | T9: 1 | U9: 0 | V9: 2 | W9: 1 | X9: N°2022-00406329 | Y9: POR REGULARIZAR | AB9: FFAA | AC9: =COUNTIF(N6:N598,"FFAA") -> 3
A10: 5 | B10: PER-BSIA040101-005 | C10: R.D. N° 006-2022 DIGDOT/MINSA | D10: 44874 | E10: 44909 | F10: 31854 | G10: II-E | H10: GERESA AREQUIPA | I10: CLÍNICA SERMEDIAL | K10: AREQUIPA | L10: AREQUIPA | M10: CALLE FRANCISCO IBÁÑEZ N° 100 UMACOLLO | N10: PRIVADO | O10: Ing. PAOLA ZAMALLOA ARANIBAR (ADMINIST) | P10: Cel: 958790652 | Q10: Médica especialista en Anatomía Patológica y Lab. Clínico Gonzales Durand Yvonne | R10: Cel: 959915177 correo: yvonnegonzalesd@gmail.com | S10: Médico en Anatomía Patológica y Lab. Clínico Gonzales Durand Yvonne, T.M. Diana Aide Herrera Paredes, Bióloga Nadia Carmela Santos, Bióloga Shirley Sandra Campos Beltrán, Biólogo Daniel Santos Lique Zurita | T10: 0 | U10: 1 | V10: 1 | W10: 3 | X10: N° 2022-0046422, N° 2022-0054509 | Y10: POR REGULARIZAR | AB10: PNP | AC10: =COUNTIF(N6:N599,"PNP") -> 0
A11: 6 | B11: PER-BSIA040107-006 | C11: R.D. N° 009-2022 DIGDOT/MINSA | D11: 44880 | E11: 44909 | F11: 17588 | G11: II-E | H11: GERESA AREQUIPA | I11: CLÍNICA DE REPRODUCCIÓN Y GENÉTICA - CLÍNICA MELO | J11: JACOBO HUNTER | K11: AREQUIPA | L11: AREQUIPA | M11: CALLE NICARAGUA L-10 | N11: PRIVADO | O11: Dr. BERNABÉ ROGELIO MELO DUEÑAS | P11: Cel: 993061742 | Q11: Médica Patóloga Clínica Yesica Zevallos Molleda | R11: Cel: 977129135 correo: yesicazemo28@hotmail.com | S11: Médica Patóloga Clínica Yesica Zevallos Molleda, T.M. José Carlos Martínez Montes, Bióloga Rocío Zevallos Cayro | T11: 1 | U11: 0 | V11: 1 | W11: 1 | X11: N° 2022-0045974, N° 2022-0054567 | Y11: POR REGULARIZAR | AB11: APP | AC11: =COUNTIF(N6:N600,"APP") -> 0
A12: 7 | B12: PER-BSIA150121-007 | C12: R.D. N° 007-2022 DIGDOT/MINSA | D12: 44874 | E12: 44909 | F12: 15077 | G12: II-E | H12: DIRIS LIMA CENTRO | I12: LIGA CONTRA EL CÁNCER - PERÚ | J12: PUEBLO LIBRE | K12: LIMA | L12: LIMA | M12: AV. BRASIL N° 2746 | N12: PRIVADO | O12: Dra. DAMARY MILLA SAAVEDRA | P12: 01 204-0404 cel: 988562238 correo: ligacancer@ligacancer.org.pe | Q12: Médica Patóloga Clínica Evelyn Norabuena Mautino | R12: Cel: 953950676 correo: evnoma@hotmail.com | S12: Médica Patóloga Clínica Evelyn Norabuena Mautino, T.M. Marañón Bendezú Ruth Guadalupe, Tec. Lab. Ana Flor Marca Pérez | T12: 1 | U12: 0 | V12: 1 | W12: 0 | X12: N° 2022-0061080, N° 2022-0069696 | Y12: POR REGULARIZAR | AC12: =SUM(AC6:AC11) -> 309
A13: 8 | B13: PER-BSIA040126-008 | C13: R.D. N° 011-2022 DIGDOT/MINSA | D13: 44893 | E13: 44907 | F13: 25732 | G13: II-E | H13: GERESA AREQUIPA | I13: NOVA CLINIC EXCELLENCE S.A.C. - NOVA CLÍNICA QUIRÚRGICA | J13: YANAHUARA | K13: AREQUIPA | L13: AREQUIPA | M13: CALLE ALFONSO UGARTE N° 652 | N13: PRIVADO | O13: Dra. JAQUELINE CRUZ VARGAS | P13: novaclinicarequipa@gmail.com | Q13: Médica Patóloga Clínica Cecilia Manrique Sam | R13: Cel: 989687151; correo: mcmanriques1@hotmail.com | S13: Médica Patóloga Clínica Cecilia Manrique Sam, T.M. Claudia del Pilar Molleda Huerta, T.M. Gabriela Sofía Manrique Almenara, T.M. Juan Alberto Ccallata Arizaca, Bióloga Jessika Paola Pickman Medina | T13: 1 | U13: 0 | V13: 3 | W13: 1 | X13: N° 2022-0075211, N° DIGDOT20220000451 | Y13: POR REGULARIZAR
A14: 9 | B14: PER-BSIA150136-009 | C14: R.D. N° 012-2022 DIGDOT/MINSA | D14: 44895 | E14: 44999 | F14: 8564 | G14: II-1 | H14: DIRIS LIMA CENTRO | I14: HOSPITAL I OCTAVIO MONGRUT MUÑOZ | J14: SAN MIGUEL | K14: LIMA | L14: LIMA | M14: AVENIDA PARQUE LAS LEYENDAS N° 255 | N14: ESSALUD | O14: Dr. Roger Augusto, BEVILACQUA WONG | P14: roger.bevilacqua@essalud.gob.pe | Q14: Medico Patologo Oscar Daniel Alama Bazan | R14: Cel: 941423820 correo: | S14: Médico Patólogo Clínico Oscar Daniel Alama Bazan, T.M. Cristina Morals Peña, T.M. Angel Leiva Bazan, T.M.Giovanna Granda Carrion, T.M. Francisco Ortiz Canasa, T.M.Alba Vilca Cabana | T14: 1 | U14: 0 | V14: 5 | W14: 0 | X14: N° 2022-0074635 , N° 2022-0084778 | Y14: POR REGULARIZAR
A15: 10 | B15: PER-BSIA130101-010 | C15: R.D. N° 013-2022 DIGDOT/MINSA | D15: 44895 | E15: 44909 | F15: 33905 | G15: II-E | H15: GERESA LA LIBERTAD | I15: CLIN.ZEGARRA-CIRUG.PLAST.Y MED.ESTET.SAC – CLÍNICA ZEGARRA SAC | J15: TRUJILLO | K15: TRUJILLO | L15: LA LIBERTAD | M15: CALLE SAN ANDRÉS N° 356 | N15: PRIVADO | O15: ANTERO WALTER ZEGARRA CARRANZA (Gerente General) | P15: CEL: 943360743 EMAIL: CLINICAZEGARRA.TRUJILLO@GMAIL.COM | Q15: MÉDICO PATÓLOGO CLÍNICO KAREN CASTILLO MINAYA | R15: CEL: 943868974 EMAIL: KAREN_YACAMI@YAHOO.COM | S15: M.C. KAREN CASTILLO MINAYA, T.M ANA MARÍA ARTEAGA CHAVEZ, T.M. YENI MARILU ROLDAN ARTEAGA | T15: 1 | U15: 0 | V15: 2 | W15: 0 | X15: N° 2022-0082167 | Y15: CLINICA PADRE LUIS TEZZA | AB15: DEPARTAMENTO | AC15: CANTIDAD
A16: 11 | B16: PER-BSIA120501-011 | C16: R.D. N° 018-2022 DIGDOT/MINSA | D16: 44897 | E16: 44908 | F16: 519 | G16: II-1 | H16: DIRESA JUNIN | I16: RED DE SALUD JUNIN - HOSPITAL DE APOYO JUNIN | J16: JUNIN | K16: JUNIN | L16: JUNIN | M16: JR. SAENZ PEÑA N° 690 - LADO OESTE | N16: MINSA | O16: Fredy Quispe Gomez | P16: dirsaludjunin@gmail.com, yuriach@gmail.com | Q16: DR. YURI ALIAGA CHAVEZ | R16: Cel: 940309513 - Correo: yuriach@gmail.com | S16: Médico Cirujano Yuri Aliaga Chavez, TM Victor Quesquen Carrillo, TM Nancy Luz Cedano Clemente, TM Diana Angela Saravia Pamo | T16: 0 | U16: 1 | V16: 1 | W16: 1 | X16: N° 2022-0073653 | Y16: POR REGULARIZAR | AB16: AREQUIPA | AC16: =COUNTIF($L$6:$L$595,AB16) -> 27
A17: 12 | B17: PER-BSIA120101-012 | C17: R.D. N° 016-2022 DIGDOT/MINSA | D17: 44897 | E17: 44926 | F17: 25973 | G17: II-E | H17: DIRESA JUNIN | I17: CLINICA ZARATE E.I.R.L. | J17: HUANCAYO | K17: HUANCAYO | L17: JUNIN | M17: AV. URUGUAY N° 533 | N17: PRIVADO | O17: Dr. Diego Matos Knutsen | P17: mariazaratecristobal27@gmail.com | Q17: Dra. Kellina Almora León | R17: Cel: 944828131 correo: walterpando@hotmail.com | S17: Dra. Kellina Almora León, T.M. Wendy Palomino Lazo, T.M.Sheyla Aranda Sanabria | T17: 0 | U17: 1 | V17: 2 | W17: 0 | X17: N° 2022-0076348 | Y17: POR REGULARIZAR | AB17: CAJAMARCA | AC17: =COUNTIF($L$6:$L$595,AB17) -> 17
A18: 13 | B18: PER-BSIA150501-013 | C18: R.D. N° 019-2022-DIGDOT/MINSA | D18: 44900 | E18: 44999 | F18: 29024 | G18: II-E | H18: DIRESA LIMA | I18: CLÍNICA DANIEL ALCIDES CARRIÓN CAÑETE E.I.R.L. | J18: SAN VICENTE DE CAÑETE | K18: CAÑETE | L18: LIMA | M18: URB. BEATO JOSEMARIA ESCRIBA DE BALAGUER LOS REYES I-16 | N18: PRIVADO | O18: Dra. BELLA MILAGROS ALEGRÍA LOZANO | P18: milagrosalegria30@hotmail.com | Q18: Dr. Zahnder Cubas Bances (YA NO ES JEFE) | R18: Cel: 965606523 correo: zahndercubas@gmail.com | S18: Médico Patólogo Clínico Zahnder Cubas Bances, Tecnóloga Médica Mayra Paulina Estrada Muñoz, Tecnólogo Médico Gustavo Ricardo Cama Cruz | T18: 1 | U18: 0 | V18: 2 | W18: 0 | X18: N° 2022-0069311, N° 2022-0091413 | Y18: POR REGULARIZAR | AB18: CALLAO | AC18: =COUNTIF($L$6:$L$595,AB18) -> 2
A19: 14 | B19: PER-BSIA120114-014 | C19: R.D. N° 021-2022 DIGDOT/MINSA | D19: 44909 | E19: 44926 | F19: 25383 | G19: II-E | H19: DIRESA JUNIN | I19: CLINICA MEDICO QUIRURGICO HUANCAYO E.I.R.L | J19: EL TAMBO | K19: HUANCAYO | L19: JUNIN | M19: AV.HUANCAVELICA NRO 1285 | N19: PRIVADO | O19: LEONARDO ENRIQUE GUILLERMO CUBAS | P19: clinicahuancayo@gmail.com , Cel: 955742727 | Q19: Medico Patologo Clinico Julio Troncoso Mena | R19: Cel: 947803062 | S19: Medico Patologo Clinico Julio Troncoso Mena | T19: 1 | U19: 2 | V19: 2 | W19: 0 | X19: N°2022-0080981 | Y19: POR REGULARIZAR | AB19: CUSCO | AC19: =COUNTIF($L$6:$L$595,AB19) -> 22
A20: 15 | B20: PER-BSIA100101-015 | C20: R.D. N° 022-2022 DIGDOT/MINSA | D20: 44909 | E20: 44926 | F20: 21062 | G20: II-E | H20: DIRESA HUANUCO | I20: CLÍNICA SAN JUAN BOSCO E.I.R.L. | J20: HUÁNUCO | K20: HUÁNUCO | L20: HUANUCO | M20: JR. DOS DE MAYO N° 1616 | N20: PRIVADO | O20: ALVARO FABRICIO FERNANDEZ PORTUGAL | P20: CEL 962819802 | Q20: MÉDICO ANATOMO PATÓLOGO CARLOS ALAN ESTELA CHAVEZ | R20: CEL: 948675874 | S20: T.M. GERMAN ANTONIO CAYO LOAYZA, T.M. CRISTOBAL ANTONIO BAUTISTA ESCOBAR | T20: 0 | U20: 1 | V20: 2 | W20: 0 | X20: N°2022-0097818 | Y20: POR REGULARIZAR | AB20: HUANCAVELICA | AC20: =COUNTIF($L$6:$L$595,AB20) -> 4
A21: 16 | B21: PER-BSIA150132-016 | C21: R.D. N° 026-2022 DIGDOT/MINSA | D21: 44916 | E21: 44926 | F21: 9090 | G21: II-1 | H21: DIRIS LIMA CENTRO | I21: PROMOTORA ASISTENCIAL S.A.C CLÍNICA LIMATAMBO-PROMOSA CLINICA LIMATAMBO SEDE SJL | J21: SAN JUAN DE LURIGANCHO | K21: LIMA | L21: LIMA | M21: AV. PROCERES DE LA INDEPENDENCIA N° 2701 | N21: PRIVADO | O21: EDGARDO BERTILO MALPARTIDA FANTINI | P21: Jsalazar@clinicalimatambo.com | Q21: Medico Patologo .Carmen Estacio Rojas | R21: 942822764 Administradora Srta jazmin Fernandez | S21: T.M EDUAR PAUL CAYETANO MENDEZ , T.M . JESSICA AIMA HUALLPA | T21: 1 | U21: 0 | V21: 2 | W21: 0 | X21: N°2022-0096450 - 2022-0107117 | Y21: POR REGULARIZAR | AB21: HUANUCO | AC21: =COUNTIF($L$6:$L$595,AB21) -> 6
A22: 17 | B22: PER-BSIA120114-017 | C22: R.D. N° 025-2022 DIGDOT/MINSA | D22: 44916 | E22: 44926 | F22: 25970 | G22: II-1 | H22: DIRESA JUNIN | I22: CLINICA REBAGLIATI | J22: EL TAMBO | K22: HUANCAYO | L22: JUNIN | M22: CALLE PIRITA N°191 | N22: PRIVADO | O22: Dr. Geovanny Paucar Condori | P22: clinicarebagliati@hotmail.com | Q22: Medico Hematologo Walter Italo Pando Rojas | R22: Cel: 968348797 correo: walterpando@gmail.com | S22: LIC. TECNOLOGO DANNA DELISA TERRAZOS ROMERO, TEC. LUZ MILAGROS DE LA CRUZ CURAZZI | T22: 0 | U22: 1 | V22: 1 | W22: 0 | X22: N° 2022-0082757, N°2022-0101004 | Y22: POR REGULARIZAR | AB22: ICA | AC22: =COUNTIF($L$6:$L$595,AB22) -> 11
A23: 18 | B23: PER-BSIA150122-018 | C23: R.D. N° 024-2022 DIGDOT/MINSA | D23: 44916 | E23: 46135 | F23: 11849 | G23: II-E | H23: DIRIS LIMA CENTRO | I23: CLINICA MIRAFLORES S.A.C | J23: MIRAFLORES | K23: LIMA | L23: LIMA | M23: AV. JOSE ENCINAS N° 141 | N23: PRIVADO | O23: DR. Agusto Felipe Ascenzo Aparicio | P23: ginefert@igf.com.pe / 016109696 | Q23: Médico Patólogo Dra. Ana Maria Corilloclla Flores | R23: 990006975 | S23: TM KAREN HUAMANI CAJALEON, TM MAGDA DEL ROSARIO NUNAYALLE VARGAS, TM DUBRASKA YETSEBELL GONZALES MORA, TM RUTH DOMINGUEZ TRUJILLO, BLG LUZ ANGELA LAZARTE GALVAN | T23: 1 | U23: 1 | V23: 3 | W23: 1 | X23: N° 2022-0089026, N°2022-0109023 | Y23: CLINICA ANGLOAMERICANA | AB23: JUNIN | AC23: =COUNTIF($L$6:$L$595,AB23) -> 10
A24: 19 | B24: PER-BSIA090301-019 | C24: R.D. N° 002-2023 DIGDOT/MINSA | D24: 44930 | E24: 44949 | F24: 3943 | G24: II-1 | H24: DIRESA HUANCAVELICA | I24: HOSPITAL DE LIRCAY | J24: LIRCAY | K24: ANGARAES | L24: HUANCAVELICA | M24: AV. ESMERALDA S/N BELLAVISTA | N24: MINSA | O24: DR.JUAN OTAÑE RODRIGUEZ | P24: juan_a2108@hotmail.com , Hospitaldelircay_Ang_Hvca@Outlook.com | Q24: Medico General Yim Ivan Mauri Vasquez | R24: Obta.Ramos 982503800 | S24: Medico General Yim Ivan Mauri Vasquez | T24: 0 | U24: 1 | V24: 4 | W24: 0 | X24: N° 2022-0099202, 2022-0087051 y 2022-0117080 | Y24: POR REGULARIZAR | AB24: LA LIBERTAD | AC24: =COUNTIF($L$6:$L$595,AB24) -> 18
A25: 20 | B25: PER-BSIA140101-020 | C25: R.D. N° 001-2023 DIGDOT/MINSA | D25: 44930 | E25: 44949 | F25: 29146 | G25: II-E | H25: GERESA LAMBAYEQUE | I25: CLINICA SAN EDUARDO - CLINICA FLORIAN S.A.C. | J25: CHICLAYO | K25: CHICLAYO | L25: LAMBAYEQUE | M25: CALLE 7 DE ENERO SUR 264 | N25: PRIVADO | O25: DR. JUAN JULIO FLORIAN CABELLOS | P25: laboratorios.saneduardo@gmail.com | Q25: Medico Patologo: Dra. Angela Yovera Puican | R25: Cel: 978835551 - anyi130@hotmail.com | S25: Medico Patologo: Angela Yovera Puican , Blg. Cinthia Rojas Muñoz , TM. Morales Nunez Olga, TM. Anderson Ramos Diaz | T25: 1 | U25: 0 | V25: 2 | W25: 1 | X25: N° 2022-0090255 | Y25: POR REGULARIZAR | AB25: LAMBAYEQUE | AC25: =COUNTIF($L$6:$L$595,AB25) -> 9
A26: 271 | B26: PER-BSIA110201 -273 | C26: R.D N°090-2025-DIGDOT/MINSA | D26: 45887 | E26: 45889 | F26: 10559 | G26: II-1 | H26: DIRESA ICA | I26: CLINICA DANIEL A. CARRION | J26: CHINCHA ALTA | K26: CHINCHA | L26: ICA | M26: AV. IDELFONSO Nº 226 - JR. LIMA N° 566 | N26: PRIVADO | O26: ALFONSO ORMEÑO VILLA | P26: cdacsa@hotmail.com | Q26: ALICIA ANTOINETTE ARIZOLA AGUADO | R26: 950999223 | S26: LIC. OLGA ARGUEDAS ANTON, LIC. MARIA NELLY MEZA ACEVEDO, LIC. MARIA DELGADO DIAZ | T26: 1 | U26: 0 | V26: 3 | W26: 0 | X26: 2025- 0137727, 2025-0157964 | Y26: POR REGULARIZAR | AB26: LIMA | AC26: =COUNTIF($L$6:$L$600,AB26) -> 98
A27: 22 | B27: PER-BSIA150117-022 | C27: R.D. N° 009-2023 DIGDOT/MINSA | D27: 44939 | E27: 44953 | F27: 17385 | G27: II-E | H27: DIRIS LIMA NORTE | I27: CLINICA SAN BARTOLOME | J27: LOS OLIVOS | K27: LIMA | L27: LIMA | M27: AV. CARLOS IZAGUIRRE N° 1142 | N27: PRIVADO | O27: JORGE ELIAS PALACIOS BAZAN | P27: clinicasanbartolome@hotmail.com | Q27: Medico Patologo: Jorge Martin Ruiz Cotrina | R27: Lic. Edison Nina: 940 249 827 | S27: Medico Patologo: Jorge Martin Ruiz Cotrina, TM. Edison Nina Carpio, TM. Reynaldo Artica Vicente, T.M. Evelyne Tracy Paredes Sipan | T27: 1 | U27: 0 | V27: 3 | W27: 0 | X27: N° 2022-0118036 y 2023-0005017 | Y27: HOSPITAL E. SERGIO BERNALES | AB27: LORETO | AC27: =COUNTIF($L$6:$L$595,AB27) -> 4
A28: 23 | B28: PER-BSIA040126-023 | C28: R.D. N° 004-2023 DIGDOT/MINSA | D28: 44938 | E28: 44953 | F28: 21966 | G28: II-E | H28: GERESA AREQUIPA | I28: INSTITUTO DE ESPECIALIDADES MÉDICAS QUIRÚRGICAS Y ONCOLÓGICAS SEÑOR DE LA MISERICORDIA - CLÍNICA ALIVIARI | J28: YANAHUARA | K28: AREQUIPA | L28: AREQUIPA | M28: CALLE LEON VELARDE N° 406 | N28: PRIVADO | O28: PATRICIO GONZALO AZÁLGARA LAZO | P28: administracion@aliviari.com | Q28: MÉDICO PATOLOGO: LUIS ANTONIO VIZCARRA ZEGARRA | R28: ADMINISTRADOR: 993380851 | S28: T.M. GUADALUPE MIRELLA COILO. TM. LEIDY YAMILET CANO QUISPE | T28: 1 | U28: 0 | V28: 2 | W28: 0 | X28: N°2022-0112741, N°2023-0003612. | Y28: POR REGULARIZAR | AB28: PIURA | AC28: =COUNTIF($L$6:$L$595,AB28) -> 17
A29: 24 | B29: PER-BSIA150113-024 | C29: R.D.N° 013-2023 DIGDOT/MINSA | D29: 44942 | E29: 44949 | F29: 20346 | G29: II-E | H29: DIRIS LIMA CENTRO | I29: SERVICIOS ASISTENCIALES SANTA BEATRIZ S.A.C. - CLINICA SANTA BEATRIZ | J29: JESUS MARIA | K29: LIMA | L29: LIMA | M29: JR. RAMON DAGNINO N° 227 | N29: PRIVADO | O29: ALEXIS ROMERO ROMERO | P29: aromero@clinicasantabeatriz.pe | Q29: Médico Patólogo: Noelia Valdez Arroyo (Cambio de jefatura, ver celda Y29) | R29: Cel. Dra Noelia Valdez.988115674 | S29: TM MIGUEL ORDERIQUE, TM DAVID MAYLLE, TM SANCHEZ MASLUCAN | T29: 1 | U29: 0 | V29: 3 | W29: 0 | X29: N°2022-0098487. N°2022-0114700 | Y29: POR REGULARIZAR | Z29: (2026) Jefe de Banco: Jesús Alberto Diaz Franco | AB29: SAN MARTIN | AC29: =COUNTIF($L$6:$L$595,AB29) -> 13
A30: 25 | B30: PER-BSIA200101-025 | C30: R.D. N° 007-2023 DIGDOT/MINSA | D30: 44938 | E30: 44953 | F30: 26928 | G30: II-E | H30: DIRESA PIURA | I30: CLINICA LA FLORIDA SAC | J30: PIURA | K30: PIURA | L30: PIURA | M30: AV. RICHARD CUSHING N° 208 - 282 | N30: PRIVADO | O30: MIGUEL ALBERTO CHAVARRI VARGAS | P30: clinicalafloridasac@outlook.com, mickychavarri@hotmail.com | Q30: Medico Patologo Clinico Kely Magali Velásquez Torres | R30: CEL DR.CHAVARRI: 968 956 825 | S30: Medico Patologo Clinico Kely Magali Velásquez Torres | T30: 1 | U30: 0 | V30: 5 | W30: 0 | X30: N° 2023-0000322, N°2023-0000788 y N°2023-00048477 | Y30: POR REGULARIZAR | AB30: TACNA | AC30: =COUNTIF($L$6:$L$595,AB30) -> 3
A31: 26 | B31: PER-BSIA150113-026 | C31: R.D. N° 011-2023 DIGDOT/MINSA | D31: 44939 | E31: 44953 | F31: 26793 | G31: II-E | H31: DIRIS LIMA CENTRO | I31: NUEVA CLINICA DE LIMA SAC | J31: JESUS MARIA | K31: LIMA | L31: LIMA | M31: AV. BRASIL N° 1199 | N31: PRIVADO | O31: DR. GLYCERIO YURI ARROYO TOVAR | P31: ADMINISTRACION@BELLAFORMA.COM | Q31: MEDICO PATOLOGO: Carlos Mendoza Euribe | S31: Tecnólogo Médico: Mauro Durand Ocaña | T31: 1 | U31: 0 | V31: 1 | W31: 0 | X31: 2022-0105567 2022-0114521 2023-0003542 | Y31: POR REGULARIZAR | AB31: UCAYALI | AC31: =COUNTIF($L$6:$L$595,AB31) -> 5
A32: 27 | B32: PER-BSIA100101-027 | C32: R.D. N° 010-2023 DIGDOT/MINSA | D32: 44939 | E32: 44953 | F32: 11592 | G32: II-E | H32: DIRESA HUANUCO | I32: CLINICA HUANUCO E.I.R.L. | J32: HUÁNUCO | K32: HUÁNUCO | L32: HUANUCO | M32: JR. CONSTITUCION N° 980 | N32: PRIVADO | O32: FAUSTINIANO VENTURO CASTRO | P32: clinicahuanuco@hotmail.com | Q32: MÉDICO ANATOMO PATÓLOGO JUAN WILDER MOTTA RODRIGUEZ | R32: Cel: 950519393 | S32: Anatomo Patológo: Motta Rodríguez Juan Wilder, TM.Cayo Loayza German Antonio, TM. Bautista Escobar Cristóbal Antonio | T32: 0 | U32: 1 | V32: 2 | W32: 0 | X32: N° 2022-0114184 y N° 2022- 0118569 | Y32: HOSPITAL REGIONAL HERMILIO VALDIZAN MEDRANO | AB32: MOQUEGUA | AC32: =COUNTIF($L$6:$L$595,AB32) -> 2
A33: 28 | B33: PER-BSIA250101-028 | C33: R.D. N° 014-2023 DIGDOT/MINSA | D33: 44949 | E33: 44956 | F33: 13055 | G33: II-1 | H33: DIRESA UCAYALI | I33: CLINICA FERNANDEZ S.R.L | J33: CALLERIA | K33: CORONEL PORTILLO | L33: UCAYALI | M33: AV.SAENZ N°150 | N33: PRIVADO | O33: JORGE FERNANDEZ PICON | P33: MESADEPARTES@CLINICAFERNANDEZ.PE | Q33: MEDICO PATOLOGO MELENDEZ GENARO RICHARD 953935675 | R33: 953935675 -GERENTE 961671002 JORGE FERNANDEZ | S33: TECNOLOGO MEDICO, MIRANDA PEREZ BARTOLOME MARLENI, NORMA RIOS CHANG , BLGO CELSO CASTILLO CUEVA | T33: 1 | U33: 0 | V33: 2 | W33: 1 | X33: N°2022-0085940,N°20220107025 Y N°2023-0005994 | Y33: POR REGULARIZAR | AB33: ANCASH | AC33: =COUNTIF($L$6:$L$595,AB33) -> 14
A34: 29 | B34: PER-BSIA40101-029 | C34: R.D. N° 015-2023 DIGDOT/MINSA | D34: 44949 | E34: 44956 | F34: 24208 | G34: II-E | H34: GERESA AREQUIPA | I34: PRAXIS MEDICAL S.A.C. | J34: AREQUIPA | K34: AREQUIPA | L34: AREQUIPA | M34: AV. SALAVERRY N°422 | N34: PRIVADO | O34: PERCY JESUS NUÑEZ VILLAR | P34: ASISTENTE@CLINICAESTETICALASER.COM | Q34: MEDICO PATOLOGO CARAZAS PORTOCARRERO MILAGROS ALINA | R34: 982709916 | S34: Médico Patólogo Carazas Portocarrero Milagros, Parada Carmen Zoila biólogo | T34: 1 | U34: 0 | V34: 0 | W34: 1 | X34: N°2023-0000476 Y N°2023-0008568 | Y34: POR REGULARIZAR | AB34: AMAZONAS | AC34: =COUNTIF($L$6:$L$595,AB34) -> 7
A35: 30 | B35: PER-BSIA200101-030 | C35: R.D. N°016 -2023 DIGDOT/MINSA | D35: 44949 | E35: 44957 | F35: 32672 | H35: DIRESA PIURA | I35: HOSPITAL PRIVADO SAN BENITO SCRL | J35: PIURA | K35: PIURA | L35: PIURA | M35: AV. ANDRÉS AVELINO CÁCERES CON INTERSECCIÓN AV. FORTUNATO CHIRICHIGNO MZ. C LTE. 3 URB. EL CHIPE | N35: PRIVADO | O35: SARITA YUVIANA CAMPOS CASTILLO | P35: clinicasanbenitopiura@gmail.com | Q35: MEDICO PATOLOGO CLINICO MARIA FRANCESCA TASSARA CICCHINI | R35: 966198468 | S35: MEDICO PATOLOGO CLINICO SANCHEZ AGUIRRE ROCIO ELIZABETH/TM NORMA YESENIA VALENCIA VALVERDE/TM FLOR DE MARIA ZAPATA CORONADO/ TM ORTIZ MOROCHO CARMEN DEL PILAR/ TM VANESSA IVON PANTA CRUZ | T35: 1 | U35: 0 | V35: 5 | W35: 0 | X35: N°2022-0108315; N°2022-0116644; N° 2023-0007437 | Y35: POR REGULARIZAR | AB35: TUMBES | AC35: =COUNTIF($L$6:$L$595,AB35) -> 1
A36: 31 | B36: PER-BSIA060401-031 | C36: R.D. N° 018-2023 DIGDOT/MINSA | D36: 44951 | E36: 44957 | F36: 32601 | G36: II-1 | H36: DIRESA CAJAMARCA | I36: HOSPITAL MODULAR BICENTENARIO CHOTA "GILBERTO VILLENA ARROBAS" | J36: CHOTA | K36: CHOTA | L36: CAJAMARCA | M36: COMUNIDAD PINGOBAMBA BAJO S/N | N36: ESSALUD | O36: LUIS ANTONIO MENDOZA URRUTIA | P36: MENDOZAU@ESSALUD.GOB.PE | Q36: MÉDICO PATÓLOGO CLÍNICO HARLEIN JEANCARLO OBLITAS VÁSQUEZ | R36: 951552714 | S36: TECNÓLOGA MÉDICA CORONEL GAVIDIA | T36: 1 | U36: 0 | V36: 1 | W36: 0 | X36: N°2023-0001785 | Y36: POR REGULARIZAR | AB36: MADRE DE DIOS | AC36: =COUNTIF($L$6:$L$595,AB36) -> 1
A37: 32 | B37: PER-BSIA90701-033 | C37: R.D. N° 019-2023 DIGDOT/MINSA | D37: 44953 | E37: 44960 | F37: 4074 | G37: II-1 | H37: DIRESA HUANCAVELICA | I37: HOSPITAL DE PAMPAS DE TAYACAJA | J37: PAMPAS | K37: TAYACAJA | L37: HUANCAVELICA | M37: JR. BOLIVAR N° 421 | N37: MINSA | O37: Dra. ERIKA OCHOA MUÑOZ | P37: hospitalpampas@regionhuancavelica | Q37: MEDICO GENERAL: YULIANA ERIKA SEGOVIA CORDOVA | R37: CEL. 976174286 | T37: 0 | U37: 1 | V37: 3 | W37: 1 | X37: N°2022-0101259 | Y37: POR REGULARIZAR | AB37: APURIMAC | AC37: =COUNTIF($L$6:$L$595,AB37) -> 3
A38: 33 | B38: PER-BSIA220901-034 | C38: R.D. N° 022-2023 DIGDOT/MINSA R.D. N° 054-2024 DIGDOT/MINSA | D38: 03/02/2023 28/08/2024 | E38: 07/02/2023 02/09/2024 | F38: 16411 | H38: DIRESA SAN MARTIN | I38: Corporación Médica San Martín SAC- CORPOMEDIC SAC (SUSP DEFINITIVA) | J38: TARAPOTO | K38: SAN MARTIN | M38: Jr. Nicolás de Piérola N°162 Tarapoto | O38: AUGUSTO RICARDO LLONTOP REATEGUI (Gerente General) JONATHAN LEE AREVALO PINCHI (Gerente Administrativo) | P38: CORPOMEDIC.ADM@GMAIL.COM | Q38: MEDICO PATOLOGO LUIS ALBERTO ABAD POZO | R38: CEL. 972047244 | S38: -Tecnólogo Medico: Verónica López Vargas, -Tecnólogo Medico: Marco Castillo Rojas | T38: 1 | U38: 0 | V38: 2 | W38: 0 | X38: N°2023-0002572 | Y38: POR REGULARIZAR | AB38: AYACUCHO | AC38: =COUNTIF($L$6:$L$595,AB38) -> 7
A39: 34 | B39: PER-BSIA150133-035 | C39: R.D. N° 028-2023 DIGDOT/MINSA | D39: 44960 | E39: 44972 | F39: 28244 | G39: II-E | H39: DIRIS LIMA SUR | I39: ONCOVIDA SERVICIOS MEDICOS E.I.R.L - CLINICA SAGRADA FAMILIA DEL SUR | J39: SAN JUAN DE MIRAFLORES | K39: LIMA | L39: LIMA | M39: Jr. BUENA AVENTURA AGUIRRE N°1229 MZ D1, SUB-LOTE 01, ZONA C2 | N39: PRIVADO | O39: Eduardo Mori Gonzáles | P39: clinicasagradafamiliadelsur@gmail.com | Q39: Medico Patologo Hernán Jaime Razo Quispe | R39: 993971792 | S39: -Tecnólogo Medico: Cesar Enrique Aguilar -Tecnólogo Medico: Tudela Leidi López | T39: 1 | U39: 0 | V39: 2 | W39: 0 | X39: N°2023-0000891 | Y39: POR REGULARIZAR | AB39: PASCO | AC39: =COUNTIF($L$6:$L$595,AB39) -> 3
A40: 35 | B40: PER-BSIA150140-036 | C40: R.D. N° 023-2023 DIGDOT/MINSA | D40: 44960 | E40: 44964 | F40: 11113 | G40: II-E | H40: DIRIS LIMA SUR | I40: INSTITUTO DE GINECOLOGÍA Y REPRODUCCIÓN S.A. - CLÍNICA MONTERRICO | J40: SANTIAGO DE SURCO | K40: LIMA | L40: LIMA | M40: AV. MANUEL OLGUÍN N° 1047 | N40: PRIVADO | O40: Jose Javier Perez Ramirez | Q40: Dra. Maria Cristina Mattos Pucahuaranga, medico patologo clinico | S40: TECNOLOGO MEDICO: EDUARDO QUINTANA QUINTANA | T40: 1 | U40: 0 | V40: 2 | W40: 0 | Y40: CLINICA ANGLOAMERICANA | AB40: PUNO | AC40: =COUNTIF($L$6:$L$595,AB40) -> 4
A41: 36 | B41: PER-BSIA120114-037 | C41: R.D. N° 025-2023 DIGDOT/MINSA | D41: 44960 | E41: 44967 | F41: 27694 | G41: II-E | H41: DIRESA JUNIN | I41: INVERSIONES M&M VALENTINA S.A.C.- CHENET CLINICA ESPECIALIZADA | J41: EL TAMBO | K41: HUANCAYO | L41: JUNIN | M41: CALLE REAL N° 612 (ESQUINA CON JR. PARRA DEL RIEGO) | N41: PRIVADO | O41: Luis Vladimir CHENET ROJAS | P41: clinicachenethyo@gmail.com | Q41: MEDICO PATOLOGO CLINICO: JULIO TRONCOSO MENA | R41: 942724995( LIC. | S41: MEDICO PATOLOGO CLINICO: Castro Germana Lorenzo José, Tecnóloga Médica: Lozada Seijas Iliani Esperanza, Tecnóloga Médica: González Morillo Jhoannaily Josefina, Tecnóloga Médica:Guevara Huamán Silvia Marlene | T41: 1 | U41: 0 | V41: 3 | W41: 0 | X41: N° 2022-0118525 y N° 2023- 0015681 | Y41: POR REGULARIZAR | AC41: =SUM(AC16:AC40) -> 308
A42: 37 | B42: PER-BSIA120101-038 | C42: R.D. N° 026-2023 DIGDOT/MINSA | D42: 44960 | E42: 44967 | F42: 24425 | G42: II-E | H42: DIRESA JUNIN | I42: CLÍNICA MÉDICA SALAZAR S.A.C | J42: HUANCAYO | K42: HUANCAYO | L42: JUNIN | M42: JR. FRANCISCO SOLANO N°142. HUANCAYO | N42: PRIVADO | O42: MILTON ANTONIO TELLO CRUZ | P42: CLINICAMEDICASALAZAR@GMAIL.COM | Q42: MÉDICO PATÓLOGO CLÍNICO JULIO TRONCOSO MENA | R42: 947803062 | S42: T.M. GIANELLA NAVARRO JAVIER, LEYDI MILENA MIGUEL MEZA, KARL NORBERT EGOAVIL SANTISTEBAN, ABEL DAYAN QUINTANA VELIZ | T42: 1 | U42: 0 | V42: 4 | W42: 0 | X42: N° 2022-0098735 y N° 2023-0016272 | Y42: POR REGULARIZAR
A43: 38 | B43: PER-BSIA220201-039 | C43: R.D. N° 024-2023 DIGDOT/MINSA | D43: 44960 | E43: 44967 | F43: 6502 | G43: II-E | H43: DIRESA SAN MARTIN | I43: HOSPITAL II-E BELLAVISTA | J43: BELLAVISTA | K43: BELLAVISTA | L43: SAN MARTIN | M43: JR APURIMAC S/N CON JR. ANCASH S/N | N43: MINSA | O43: OBST. LING ISAC WELING FLORES PEREZ | P43: hospital2ebellavista@gmail.com | Q43: M.C. WHINSTON ENRIQUE PEREZ RAMIREZ (JEFE DPTO PAT CLIN Y ANAT PAT) | R43: DR WHINSTON PEREZ: 923906086 | S43: T.M CALLE TUCTO, BLG: LILIANA MEDINA ACHIN, ALARCON MOZOMBITE EDWAR,BLG SILVA ORE SEGUNDO, BLG VARGAS PEÑA IRIS, BLG PAYANO LOPEZ WALDO, BLG SAAVEDRA FLORES JAQUELIN | T43: 1 | U43: 0 | V43: 1 | W43: 5 | X43: N° 2022-0098843, N°2023-00000816, N°2023-0012795, N°2023-0014440, N°2023-0014432 | Y43: BANCO DE SANGRE REGIONAL SAN MARTIN
A44: 39 | B44: PER-BSIA220201-040 | C44: R.D. N° 027-2023 DIGDOT/MINSA | D44: 44960 | E44: 44967 | F44: 16951 | G44: II-E | H44: DIRIS LIMA NORTE | I44: CLINICA MATER PURISSIMA | J44: COMAS | K44: LIMA | L44: LIMA | M44: JR. GARCILASO DE LA VEGA N° 191 Y MARIANO MELGAR 164 MZ G LOTE 1 Y 2 | N44: PRIVADO | O44: Miguel Angel Cerna Cornelio | P44: maccch@hotmail.com | Q44: MEDICO PATOLOGO: SAN MARTIN CHIPOCO VICTOR | R44: LIC T.M CARLOS LEYVA: 980738750 | S44: T.M LEYVA VASQUEZ CARLOS, T.M ROJAS MEJIA HARRY, T.M VELARDE ALBITES JOSE | T44: 1 | U44: 0 | V44: 3 | W44: 0 | X44: Expediente: 2023-0008520 | Y44: POR REGULARIZAR
...

Sheet BS I B
A4: BANCO DE SANGRE TIPO I B | AA4: MINSA 5 ESSALUD 3 FFAA 0 | AD4: -
A5: N° | B5: N° DE INSCRIPCIÓN | C5: ACTO RESOLUTIVO | D5: FECHA (DIA/MES/AÑO) | E5: FECHA DE PUBLICACION RD | F5: RENIPRESS | G5: CATEGORIA | H5: DIRIS/DIRESA | I5: IPRESS | J5: DISTRITO | K5: PROVINCIA | L5: REGION | M5: DIRECCIÓN | N5: SUBSECTOR | O5: DIRECTOR | P5: CONTACTO | Q5: JEFE DE BANCO DE SANGRE | R5: CONTACTO | S5: PERSONAL | T5: Patólogo Clínico | U5: Otra Especial | V5: T.M. | W5: Biól. | X5: N° EXPEDIENTE | Y5: CONVENIO | AA5: PRIVADO | AB5: =COUNTIF(N6:N601,"PRIVADO") -> 39
A6: 1 | B6: PER-BSIB131001-001 | C6: R.D. N° 008-2022 DIGDOT/MINSA | D6: 44874 | E6: 44909 | F6: 5332 | G6: II-1 | H6: GERESA LA LIBERTAD | I6: HOSPITAL CESAR VALLEJO MENDOZA | J6: SANTIAGO DE CHUCO | K6: SANTIAGO DE CHUCO | L6: LA LIBERTAD | M6: CALLE MARISCAL CÁCERES N° 1145 | N6: MINSA | O6: DR JORGE CABALLERO | P6: jacrmed@hotmail.com | Q6: Dra. CARLA PATRICIA RODRIGUEZ PALOMINO | S6: T.M. Heiner Vásquez Idrogo, T.M. Solange Thalía Ramos Córdova, T.M. Carlos Fernando Jimenez Ramos, Bióloga Katherine Liliana Zapata Cabañas | T6: 1 | U6: 0 | V6: 3 | W6: 1 | X6: N° 2022-0046422, N° 2022-0068637 | Y6: POR REGULARIZAR | AA6: MINSA | AB6: =COUNTIF(N6:N602,"MINSA") -> 23
A7: 2 | B7: PER-BSIB150131-002 | C7: R.D. N° 010-2022 DIGDOT/MINSA | D7: 44883 | E7: 44909 | F7: 9437 | G7: II-2 | H7: DIRIS LIMA CENTRO | I7: PROMOTORA ASISTENCIAL S.A.C CLÍNICA LIMATAMBO | J7: SAN ISIDRO | K7: LIMA | L7: LIMA | M7: AVENIDA REPUBLICA DE PANAMA N° 3606 | N7: PRIVADO | O7: DR. EDGARDO BERTILO MALPARTIDA FANTINI (GG) DR. DANIEL MONTESINOS AVILA (DM) | P7: (01) 617-1111 jsalazar@clinicalimatambo.com | Q7: MÉDICA PATÓLOGA CLÍNICA TEOFILA CARMEN ESTACIO ROJAS | R7: Cel: 999 667 910 Correo: estaciolab@hotmail.com | S7: Dra. Teófila Carmen Estacio Rojas - Médico Patólogo Clínico, Tecnóloga Médica: Jessica Aima Huallpa, Tecnólogo Médico: Edward Paul Cayetano Méndez, Tecnólogo Médico: Christopher Toledo Gamonal | T7: 1 | U7: 0 | V7: 3 | W7: 0 | X7: N° 2022-0075013, N° 2022-0084531 | Y7: HOSPITAL SANTA ROSA | AA7: ESSALUD | AB7: =COUNTIF(N6:N603,"ESSALUD") -> 19
A8: 3 | B8: PER-BSIB120301-003 | C8: R.D. N° 015-2022 DIGDOT/MINSA | D8: 44895 | E8: 45041 | F8: 8656 | G8: II-1 | H8: DIRESA JUNIN | I8: HOSPITAL SELVA CENTRAL Y ENFERMEDADES TROPICALES "HUGO PESCE PESCETTO" | J8: CHANCHAMAYO | K8: CHANCHAMAYO | L8: JUNIN | M8: JR. LOS CAUCHOS N° 223-271 Y JR. LOS ROBLES N° 527 | N8: ESSALUD | O8: DR. JULIO AZAÑA MUÑOZ | P8: julio.azana@essalud.gob.pe, gina.daniran@essalud.gob.pe | Q8: MÉDICO PATÓLOGO CLÍNICO MARIO LINARES SULLCA | R8: Cel: 943933977; mariolinares@gmail.com | S8: Médico Patólogo Clínico Mario Linares Sullca, T.M. Arias González Paul Eduardo, T.M. Paolo Félix Sedano Guerrero, T.M. Jaqueline Bellissa Cóndor Romero | T8: 1 | U8: 0 | V8: 3 | W8: 0 | X8: N° 2022-0063224, N° DIGDOT20220000469 | Y8: POR REGULARIZAR | AA8: FFAA | AB8: =COUNTIF(N6:N604,"FFAA") -> 0
A9: 4 | B9: PER-BSIB1171-004 | C9: R.D. N° 020-2022 DIGDOT/MINSA | D9: 44900 | E9: 44999 | F9: 5292 | G9: II-1 | H9: GERESA LA LIBERTAD | I9: HOSPITAL TOMAS LA FORA | J9: GUADALUPE | K9: PACASMAYO | L9: LA LIBERTAD | M9: JR AYACUCHO N° 251 | N9: MINSA | O9: ELSA CLARA LA TORRE CRUZ | P9: elsa_claral@yahoo.es | Q9: MC. JULIO CESAR RODRIGUEZ CRUZ | R9: Cel:955371669 | S9: MC. JULIO CESAR RAMIREZ CRUZ, Tecnólogo Médico: Genaro Tomas Gálvez Abanto, Tecnólogo Medico: Edy Alcides Alvarado Chomba, Tecnólogo Medico : Marcela Quiroz Casos | T9: 1 | U9: 0 | V9: 3 | W9: 0 | X9: N° 2022-2022-0093906 | Y9: POR REGULARIZAR | AA9: PNP | AB9: =COUNTIF(N6:N605,"PNP") -> 0
A10: 5 | B10: PER-BSIB150131-005 | C10: R.D. N° 003-2023 DIGDOT/MINSA | D10: 44931 | E10: 44949 | F10: 8398 | G10: II-2 | H10: DIRIS LIMA CENTRO | I10: SISTEMAS DE ADMINISTRACIÓN HOSPITALARIA S.A.C.- SANNA CLÍNICA EL GOLF | J10: SAN ISIDRO | K10: LIMA | L10: LIMA | M10: AV. AURELIO MIRO QUESADA N° 1030 | N10: PRIVADO | O10: DR. LUIS TRUJILLO POMIANO | Q10: DR GIANCARLO DEMICHELLI ARIAS | R10: 999260631 | S10: Medico Patologo clinico: Olga Margarita Lopez Odría; Tecnologos Medicos: María Elena del Carmen Mostacero Castillo, Vania Paloma Laguna Paz, Luani Nair Linares Masson, Hime Joel Granda García, Edson Jan Carlo Abanto Izquierdo ,Yohana Maricela Cienfuegos Mellado , Jonathan Velásquez Cuba, Ana María Rodríguez Apolo, Jhan Francis Canales Loayza, Carlos Ernesto Escala Soto | T10: 1 | U10: 0 | V10: 10 | W10: 0 | X10: N° 2022-0096406 , 2022-0104934 y 2022-0113634 | Y10: CLINICA SAN BORJA SANNA | AA10: APP | AB10: =COUNTIF(N6:N606,"APP") -> 0
A11: 6 | B11: PER-BSIB150101-006 | C11: R.D. N° 012-2023 DIGDOT/MINSA | D11: 44938 | E11: 44953 | F11: 6209 | G11: III-2 | H11: DIRIS LIMA CENTRO | I11: INSTITUTO NACIONAL DE CIENCIAS NEUROLOGICAS | J11: LIMA/BARRIOS ALTOS | K11: LIMA | L11: LIMA | M11: JR.ANCASH N°1271 | N11: MINSA | O11: DR. JORGE ENRIQUE MEDINA RUBIO | P11: jmedinar@incn.gob.pe, giancarlo.demichelli@gmail.com | Q11: GIANNA GIAMPETRI VANCES | R11: 980673595 | S11: MEDICO PATOLOGO : GIANCARLO DEMICHELLI, TM .CARMEN QUISPE MLEYVA | T11: 1 | U11: 0 | V11: 7 | W11: 0 | X11: N°2022-0092427 -N°2023-0004534 | Y11: POR REGULARIZAR
A12: 7 | B12: PER-BSIB150117-007 | C12: R.D. N° 021-2023 DIGDOT/MINSA | D12: 44957 | E12: 44962 | F12: 26936 | G12: II-E | H12: DIRIS LIMA NORTE | I12: CLINICA AVIVA SEDE MENDIOLA | J12: LOS OLIVOS | K12: LIMA | L12: LIMA | M12: Av. Alfredo Mendiola N°6301 | N12: PRIVADO | O12: FLOR DE MARIA DE LAS MERCEDES CALDERON ORMEÑO | P12: flor.calderon@aviva.pe | Q12: MÉDICO PATÓLOGO CLÍNICO JUAN CARLOS GOMEZ DE LA TORRE PRETELL | R12: 965378787 | S12: Dr. Juan Carlos Gómez de la Torre Pretell, Tecnólogo Medico: Rosemary Cristina Ramírez Fajardo, Tecnólogo Medico: Manuel Martin Díaz Quepuy, Tecnólogo Medico: Alexis Cárdenas Perea, Tecnólogo Medico: Keissy Milagros Paredes Guerra, Tecnólogo Medico: Jackelyne Ivette Cullas Musayon | T12: 1 | U12: 0 | V12: 5 | W12: 0 | X12: N° 2023-0000400 | Y12: POR REGULARIZAR
A13: 8 | B13: PER-BSIB150131-008 | C13: R.D. N° 029-2023 DIGDOT/MINSA | D13: 44966 | E13: 44973 | F13: 27320 | G13: II-1 | H13: DIRIS LIMA CENTRO | I13: ONCOCENTER PERÚ S.A.C. - CLÍNICA AUNA GUARDIA CIVIL | J13: SAN ISIDRO | K13: LIMA | L13: LIMA | M13: Av. Guardia Civil N° 368 | N13: PRIVADO | O13: DRA. MARTHA BIBIANA PEREZ VILLABONA | P13: mperezvi@auna.pe | Q13: MÉDICO PATÓLOGO CLÍNICO Christian Enrique Hurtado Tacuri | R13: 941365565 | S13: MÉDICO PATÓLOGO CLÍNICO Christian Enrique Hurtado Tacuri , - Tecnólogo Médico: Carhuamaca Campian Charles, Tecnólogo Médica: Enciso Meza Olga Bertha, Tecnólogo Médica: Zapata Calle Mariela, Tecnólogo Médica: Lucas Grados Lissette Isabel, Tecnólogo Médica: Verastegui Topovich Renata Patricia | T13: 1 | U13: 0 | V13: 5 | W13: 0 | X13: N° 2023-0005799, 2023-0008765 y 2023-0014273 | Y13: POR REGULARIZAR
A14: 9 | B14: PER-BSIB140101-009 | C14: R.D. N° 033-2023 DIGDOT/MINSA | D14: 44966 | E14: 45000 | F14: 30057 | G14: II-E | H14: GERESA LAMBAYEQUE | I14: GSP TRUJILLO S.A.C. - CLÍNICA AUNA SEDE CHICLAYO | J14: CHICLAYO | K14: CHICLAYO | L14: LAMBAYEQUE | M14: AV. MARISCAL NIETO N° 480 | N14: PRIVADO | O14: DRA. CARLA ELIZABETH URIARTE ALAYZA | P14: jarrue@auna.pe | Q14: MÉDICO PATÓLOGO CLINICO JOHAN ARRUE HERNANDEZ | R14: 987770649 | S14: Médico Patólogo Clínico Johan Arrue Hernández, Tecnólogos Médicos: Marilú Piscoya Soto, Luz Sánchez Ayasta, Rodorico Cieza Marín y Euber Sánchez Ramírez | T14: 1 | U14: 0 | V14: 4 | W14: 0 | X14: N° 2023-0010703 | Y14: POR REGULARIZAR
A15: 10 | B15: PER-BSIB130101-011 | C15: R.D. N° 040-2023 DIGDOT/MINSA | D15: 44972 | E15: 44984 | F15: 26935 | G15: II-1 | H15: GERESA LA LIBERTAD | I15: CLÍNICA SANTA ANA S.A.C.-CLÍNICA FÁTIMA | J15: VICTOR LARCO HERRERA | K15: TRUJILLO | L15: LA LIBERTAD | M15: AV. FÁTIMA 494 URB. CALIFORNIA | N15: PRIVADO | O15: GERENTE MARIA LUISA MAS MELENDEZ | P15: clinicafatima01@gmail.com | Q15: MÉDICO PATOÓLOGO CLÍNICO AMALIA CELINA CHAVEZ SILVA | R15: 976019199 | S15: T.M. JESSICA MARIBEL ORBEGOSO YPARRAGUIRRE T.M. ESTEFANIA ALAYO ROSALES T.M. MILAGROS LANDA PRECIADO | T15: 1 | U15: 0 | V15: 3 | W15: 0 | X15: N°2023-0014686 | Y15: HOSPITAL BELEN DE TRUJILLO | AA15: AREQUIPA | AB15: =COUNTIF($L$6:$L$601,AA15) -> 5
A16: 11 | B16: PER-BSIB220901-010 | C16: R.D. N° 041-2023 DIGDOT/MINSA | D16: 44972 | E16: 44984 | F16: 32615 | G16: II-E | H16: DIRESA SAN MARTIN | I16: CENTRO NEUROQUIRURGICO DE LA SELVA S.A.C.-CLINICA RODRIGUEZ | J16: TARAPOTO | K16: SAN MARTIN | L16: SAN MARTIN | M16: JR. Brasil N°262 | N16: PRIVADO | O16: MC. OSWALDO RODRIGUEZ MEDINA | P16: clinicarodriguez2020@hotmail.com | Q16: MÉDICO PATÓLOGO LUIS ALBERTO ABAD POZO | R16: 920 244 145 (Lic. Verónica)/ 945148273 (Patólogo James Añazgo) | S16: DR. James Añazgo Pinedo, TM. Marco Antonio Castillo Rojas, TM. Verónica Janeth López Vargas, TM Medina gallardo Marilyn | T16: 1 | U16: 0 | V16: 3 | W16: 0 | X16: N°2023-0017075 | Y16: BANCO DE SANGRE REGIONAL SAN MARTIN | AA16: DEPARTAMENTO | AB16: CANTIDAD
A17: 12 | B17: PER-BSIB130101-012 | C17: R.D. N° 056-2023 DIGDOT/MINSA | D17: 44987 | E17: 45002 | F17: 18404 | G17: II-2 | H17: GERESA LA LIBERTAD | I17: CLINICA SAN PABLO DE TRUJILLO- CLINICA LA MERCED SAC | J17: TRUJILLO | K17: TRUJILLO | L17: LA LIBERTAD | M17: AV.HUSARES DE JUNIN 690 LA MERCED | N17: PRIVADO | O17: JOSE LUIS CARRANZA CASTILLO | P17: jcarranza@sanpablo.com.pe | Q17: MEDICO PATOLOGO CLINICO CARLOS EDUARDO ESQUERRE AGUIRRE | R17: 938 339 507 | S17: LIC. TM EDWIN YULFO FONSECA ESPINOZA,LIC. TM SILVIA ELIZABETH LINO CAPRISTAN,BLG. JUANA ELIZABETH BELTRAN MORENO | T17: 1 | U17: 0 | V17: 2 | W17: 1 | X17: N° 2023-0011833, 2023-0015413 y 2023-0025830 | Y17: POR REGULARIZAR | AA17: CAJAMARCA | AB17: =COUNTIF($L$6:$L$601,AA17) -> 2
A18: 13 | B18: PER-BSIB120808-013 | C18: R.D. N° 052-2023 DIGDOT/MINSA | D18: 44985 | E18: 44999 | F18: 8653 | G18: II-1 | H18: DIRESA JUNIN | I18: HOSPITAL II ALBERTO HURTADO ABADIA | J18: SANTA ROSA DE SACCO | K18: YAULI | L18: JUNIN | M18: AVENIDA MIGUEL GRAU 1250 | N18: ESSALUD | O18: Aurelio Cordova Bravo | P18: pedro.yarascaga@essalud.gob.pe | Q18: MEDICO PATOLOGO CLINICO LINARES SULLCA MARIO | R18: 943933973 | S18: TM: Oscar Ticona Rivero, Yanqui Mamani Victoria Gladys, Cárdenas Arellano Rosa, Luis Navarro Mattos,Felix Guizado Mercado | T18: 1 | U18: 0 | V18: 5 | W18: 0 | X18: 2022-0083386, 2022-0101975, 2023-0005590, 2023-0017883 y 2023-0029793 | Y18: POR REGULARIZAR | AA18: CALLAO | AB18: =COUNTIF($L$6:$L$601,AA18) -> 3
A19: 14 | B19: PER-BSIB40103-014 | C19: R.D. N° 059-2023 DIGDOT/MINSA | D19: 44987 | E19: 45003 | F19: 15730 | G19: II-1 | H19: GERESA AREQUIPA | I19: HOGAR CLINICA SAN JUAN DE DIOS DE AREQUIPA | J19: CAYMA | K19: AREQUIPA | L19: AREQUIPA | M19: AV. EJERCITO N° 1020 | N19: PRIVADO | O19: CESAR AUGUSTO ARROYO GUTIERREZ | P19: clinicasjd.arequipa@sanjuandedios.pe / 955877185 | Q19: MED PATOLOGO CLINICO ROSARIO ELSA JESUS ZUÑIGA MANRIQUE | R19: 953759292 | S19: TM. Lesly Araujo Román, Ronald León Soto; Blgos: Flora Bobadilla Ingals, Diana Altamirano Parada,Guadalupe Luque Lázaro,Rossana Mansilla, Julio Ortega | T19: 1 | U19: 0 | V19: 2 | W19: 5 | X19: 2023-0016894, 2023-0026191, 2023-0025146 | Y19: POR REGULARIZAR | AA19: CUSCO | AB19: =COUNTIF($L$6:$L$601,AA19) -> 0
A20: 15 | B20: PER-BSIB150114-015 | C20: R.D. N° 062-2023 DIGDOT/MINSA | D20: 44992 | E20: 45003 | F20: 10135 | G20: II-1 | H20: DIRIS LIMA ESTE | I20: HOSPITAL I CARLOS ALCANTARA BUTTERFIELD | J20: LA MOLINA | K20: LIMA | L20: LIMA | M20: Av. Los Constructores 1201 - Urb. Covima | N20: ESSALUD | O20: ELIAS RODRIGUEZ SALAZAR | P20: elias.rodriguez@essalud.gob.pe | Q20: Médico Especialista En Patología Clínica Maria Graciela Neyra Mercado | R20: 994502563 | S20: TM Luisa Elizabeth Luisa Lozano Miguel, TM Elva Fatima Caballero Muñoz, TM Maria Arcelli Garcia Urbina , TM Pascuala Aurora Inga Peña, TM Eduardo Simon Paredes Lujan | T20: 1 | U20: 0 | V20: 5 | W20: 0 | X20: N°2023-0022499; N°2023-0023267; N°2023-0027091, N°2023-0034479; N°2023-0035690 y N°2023-0035735 | Y20: POR REGULARIZAR | AA20: HUANCAVELICA | AB20: =COUNTIF($L$6:$L$601,AA20) -> 0
A21: 16 | B21: PER-BSIA150121-071 | C21: R.D. N° 074-2023 DIGDOT/MINSA | D21: 45006 | E21: 45020 | F21: 8351 | G21: II-E | H21: DIRIS LIMA CENTRO | I21: CLINICAS SAN BERNARDO S.A. | J21: PUEBLO LIBRE | K21: LIMA | L21: LIMA | M21: CALLE SAN JOSE N° 161 | N21: PRIVADO | O21: MAURO MARCELO LIZARRAGA FERRAND | P21: mlizarraga@clinica-sanbernardo.com | Q21: DR. RAFAEL RODRIGUEZ BAYONA | R21: 981839312 | S21: Tecnólogo Médico: Christian Lengua Figueroa, Tecnóloga Médica: Mishell Verena Ñahuin Quispe | T21: 1 | U21: 1 | V21: 2 | W21: 0 | X21: 2023-0036348 | Y21: CLINICA SANTA LUCIA / CLINICA ANNGLOAMERICANA | AA21: HUANUCO | AB21: =COUNTIF($L$6:$L$601,AA21) -> 0
A22: 17 | B22: PER-BSIB150201-016 | C22: R.D. N° 075-2023 DIGDOT/MINSA | D22: 45012 | E22: 45019 | F22: 7635 | G22: II-2 | H22: DIRESA LIMA | I22: HOSPITAL BARRANCA CAJATAMBO SBS | J22: BARRANCA | K22: BARRANCA | L22: LIMA | M22: AV. Nicolas de Pierola N°210-221 | N22: MINSA | O22: Jack Marlon Jara Reyes | P22: direccion_ejecutiva@hospitalbarranca.gob.pe | Q22: MEDICO PATOLOGO CLINICO : ELSA ISELA SALOME TOLENTINO | R22: 9504429527 | S22: T.M: Flores Ardiles Victor Hernan, Edgar Hernesto Sanches Herrera, Luz angelica Moran de Los Santos, Cotrina Barzola, Paola Elizabeth, Kikuyo lay Iwana Amacifuen, Catherine solano Rios, Patricia Elizabeth Reyes Gallegos | T22: 1 | U22: 0 | V22: 7 | W22: 0 | X22: N° 2023-0015565, N°2023-00025959 y N°2023-0040188 | Y22: HOSPITAL DE HUACHO / INSTITUTO NACIONAL DE SALUD DEL NIÑO SAN BORJA | AA22: ICA | AB22: =COUNTIF($L$6:$L$601,AA22) -> 4
A23: 18 | B23: PER-BSIB150134-017 | C23: R.D. N° 093-2023 DIGDOT/MINSA | D23: 45035 | E23: 45042 | F23: 8786 | G23: II-1 | H23: DIRIS LIMA CENTRO | I23: CLINICA SAN JUAN DE DIOS - HOGAR CLINICA SAN JUAN DE DIOS | J23: SAN LUIS | K23: LIMA | L23: LIMA | M23: Av. Nicolas Arriola N°3250 | N23: PRIVADO | O23: FELIX ACUÑA ZAMORA | P23: felizcuña@ohsanjuandedios.org | Q23: MEDICO PATOLOGO:. Adrián Martin de Jesús Villaorduña Nahuis | R23: 983686579 | S23: Lic. T.M :Enibet Susan Salazar Mesa, Edith zandra Quispe Tecse, María Angélica Quinto Fernández, Juan Cosme Aquino Ramírez | T23: 1 | U23: 0 | V23: 4 | W23: 0 | X23: N°2023-0034808, N°2023-0051814 Y N°2023-0062016 | Y23: CONGREGACION HIJAS DE SAN CAMILO - CLINICA PADRE LUIS TEZZA | AA23: JUNIN | AB23: =COUNTIF($L$6:$L$601,AA23) -> 5
A24: 19 | B24: PER-BSIB150115-018 | C24: R.D. N° 110-2023 DIGDOT/MINSA | D24: 45056 | E24: 45058 | F24: 6212 | G24: III-E | H24: DIRIS LIMA CENTRO | I24: HOSPITAL DE EMERGENCIAS PEDIATRICAS | J24: LA VICTORIA | K24: LIMA | L24: LIMA | M24: AV. GRAU Nº 854 | N24: MINSA | O24: Tomy Villanueva Arequipeño | P24: tvillanueva@hep.gob.pe | Q24: Medico Patologo: Príncipe Laines Fortunato Martin | R24: 959682989 | S24: - Carhuamaca zarate pamela, TM.Orellano Hinojosa Luis, TM.Guzmán Garay Marco, TM.Rojas Herrera Friny, TM.Mendoza Álvarez José, TM.Vivas Hurtado Carlos., TM.Vasquez Aguirre Luz, TM.Bravo Cossio Fanny | T24: 2 | U24: 0 | V24: 8 | W24: 0 | X24: Expediente N° 2023-0033715, N° 2023-0051539 y 2023-0055599 | Y24: POR REGULARIZAR | AA24: JUNÍN | AB24: =COUNTIF($L$6:$L$601,AA24) -> 0
A25: 20 | B25: PER-BSIB140301-019 | C25: R.D. N° 126-2023 DIGDOT/MINSA | D25: 45104 | E25: 45114 | F25: 4370 | G25: II-1 | H25: GERESA LAMBAYEQUE | I25: HOSPITAL PROVINCIAL DOCENTE BELÉN - LAMBAYEQUE | J25: LAMBAYEQUE | K25: LAMBAYEQUE | L25: LAMBAYEQUE | M25: AV. RAMON CASTILLA N°597 | N25: MINSA | O25: JESUS ALFONSO YESQUEN ALBURQUERQUE | P25: HOSPITALBELEN.LAMBAYEQUE@GMAIL.COM | Q25: DR. LEONARDO ENRIQUE GARCIA MANOSALVA | R25: 979827155 | S25: DR.LEONARDO GARCIA MANOSALVA, TM. RICARDO GONZALES AYASTA, TM. BREMIDA BRAVO ASENJO, TM. EUCLIDES BACALLA VEGA, BLG. RAQUEL CASTAÑEDA MORENO, BLG. FIORELLA LOPEZ ESQUEN, TEC. TOMAS ACOSTA SUCLUPE | T25: 1 | U25: 0 | V25: 3 | W25: 2 | X25: EXPEDIENTE N° 2023-0085644 | Y25: POR REGULARIZAR | AA25: LA LIBERTAD | AB25: =COUNTIF($L$6:$L$601,AA25) -> 7
A26: 21 | B26: PER-BSIB21801-020 | C26: R.D. N° 130-2023 DIGDOT/MINSA | D26: 45105 | E26: 45118 | F26: 1652 | G26: II-2 | H26: DIRESA ANCASH | I26: HOSPITAL LA CALETA | J26: CHIMBOTE | K26: SANTA | L26: ANCASH | M26: AV. MALECON GRAU S/N | N26: MINSA | O26: FERNANDO ITURRIZAGA HERRERA | P26: mesadepartes.hlc@gmail.com | Q26: CESAR CÁCERES OTERO | R26: Cel: 970706940 Lic. Haydee | S26: Dr. Antonio José Espinoza Medina, Especialista en Patología y Laboratorio Clínico, Tecnólogo Médico: Haydee Margot Mendoza Ávila, Julio César Paredes Ramos, Silvia Albertina Vidal Carbajal, Luis Armando Hernandez Arteaga, Milagros Fatima La Jara Solano, Medaly Anais Vasquez Callan, Deysi Victoria Fernandez Castillo. | T26: 1 | U26: 0 | V26: 3 | W26: 0 | X26: Expedientes: N° 2023- 0106311, N°2023- 0119964, N° 2023- 0120818 y N° 2023- 0128833 | Y26: HOSPITAL ELEAZAR GUZMAN BARRON | AA26: LAMBAYEQUE | AB26: =COUNTIF($L$6:$L$601,AA26) -> 6
A27: 22 | B27: PER-BSIB40101-021 | C27: R.D. N° 138-2023 DIGDOT/MINSA | D27: 45133 | E27: 45145 | F27: 16744 (*) | G27: II-1 | H27: GERESA AREQUIPA | I27: CLINICAS AUNA SEDE VALLE SUR - RS: CLINICA VALLE SUR S.A | J27: AREQUIPA | K27: AREQUIPA | L27: AREQUIPA | M27: AV LA SALLE N°116 | N27: PRIVADO | O27: EDGAR EDUARDO RUIVERA DIAZ | P27: erivera@auna.pe , ,huanqui@auna.pe | Q27: DR.JUAN JOSE DIAZ ROSSEL | R27: 987059322 | S27: TM. Claudia Molleda Huerta , Juan Alberto Ccallta Arizaca, Gabriela sofia Manrique Almenara | T27: 1 | U27: 0 | V27: 3 | W27: 0 | X27: Expedientes : N°2023-0114665 , 2023-0126060 y 2023-0143911 | Y27: POR REGULARIZAR | AA27: LIMA | AB27: =COUNTIF($L$6:$L$601,AA27) -> 33
A28: 23 | B28: PER-BSIB30101-022 | C28: R.D. N° 142-2023 DIGDOT/MINSA | D28: 45146 | E28: 45152 | F28: 11213 | G28: II-2 | H28: DIRESA APURIMAC | I28: IPRESS denominada Seguro Social de Salud - ESSALUD - Hospital II Abancay | J28: ABANCAY | K28: ABANCAY | L28: APURIMAC | M28: Lote 61 Quinta Cayetana Patibamba | N28: ESSALUD | O28: JORGE PONCE JUAREZ | P28: jorge.ponce@essalud.gob.pe | Q28: DRA. KATYA ROZZANA RODRIGUEZ BERRIO | R28: 999 494 921 | S28: LIC. PAUL JUSTO CONDORI PEREZ, TM EDINSON BORDA VILLCAS, TM ZAIDA LISSETH HANCCO SOTO, TM CRISTOBAL GUTIERREZ RAMIREZ, TM EDGAR DE LA CRUZ MENDOZA, TM VICTORIA ASTOCAZA ROSALES, | T28: 1 | U28: 0 | V28: 6 | W28: 0 | X28: N° 2023-0130263 Y N°2023-0140466 | Y28: POR REGULARIZAR | AA28: LORETO | AB28: =COUNTIF($L$6:$L$601,AA28) -> 0
A29: 24 | B29: PER-BSIB150118-023 | C29: R.D. N° 144-2023 DIGDOT/MINSA | D29: 45155 | E29: 45159 | F29: 5947 | G29: II-2 | H29: DIRIS LIMA ESTE | I29: HOSPITAL DE MEDIANA COMPLEJIDAD JOSE AGURTO TELLO | J29: LURIGANCHO-CHOSICA | K29: LIMA | L29: LIMA | M29: JIRÓN JR. AREQUIPA 214 - 218 | N29: MINSA | O29: Ciro Liberato Ramon | P29: LIBERO24919@GMAIL.COM | Q29: PEDRO LUIS KOC CASTAÑEDA | R29: 969359891 | S29: LIC. TM. Andrea Yanina Condor, LIC. T.M. Fernando Zosimo Navarro Atiz, LIC. T.M. Lisseth Robles Ramos, LIC. T.M. Diana Irma Herrera Crispín , LIC. T.M. Juana Ortiz Talaverano, LIC. T.M. Máximo Llantoy Calle, LIC. T.M. Leopoldo Frank roque Morales, LIC. T.M. Mlasquez Quispe Diorella Yuly, Lic. T.M. Mery Luz Sanchez Candiotti, LIC. T.M. Willmer Galvez Huaman | T29: 1 | U29: 0 | V29: 10 | W29: 0 | X29: N°2023-0129159,N°2023-0142019, N°2023-0149364, N°2023-0152231, N°; Mediante exp N° 2024-0193107 de fecha 15/08/2024 Envian oficio informando que el Banco de Sangre fue reubicado dentro de la IPRESS, actualización de recurso humano del Banco de Sangre 2023-0162959 | Y29: POR REGULARIZAR | AA29: PIURA | AB29: =COUNTIF($L$6:$L$601,AA29) -> 5
A30: 25 | B30: PER-BSIB200101-024 | C30: R.D. N° 146-2023 DIGDOT/MINSA | D30: 45159 | E30: 45162 | F30: 25208 | G30: II-1 | H30: DIRESA PIURA | I30: IPRESS Grupo Carita Feliz S.A. | J30: PIURA | K30: PIURA | L30: PIURA | M30: Calle Huancavelica N°1039, Urb. 4 de enero | N30: PRIVADO | O30: RICARDO OLEA ZAPATA | P30: ricardo.olea@clinicacaritafeliz.com | Q30: JOEL ANCAJIMA MORE | R30: 979 374 361 | S30: TM HARLINSON PACHERRE SEMINARIO, TM NOE OLAYA NIÑO, TM YESENIA VALENCIA VALVERDE, TM JUNIOR CARMEN HERNANDEZ, TM ERNESTO CALDERON CARLOS, | T30: 1 | U30: 0 | V30: 5 | W30: 0 | X30: 2023-0144155 | Y30: POR REGULARIZAR | AA30: SAN MARTIN | AB30: =COUNTIF($L$6:$L$601,AA30) -> 6
A31: 26 | B31: PER-BSIB130101-025 | C31: R.D. N° 159-2023 DIGDOT/MINSA | D31: 45166 | E31: 45173 | F31: 16830 | G31: II-E | H31: GERESA LA LIBERTAD | I31: RS: GPS TRUJILLO SAC Y NC: CLINICA CAMINO REAL | J31: TRUJILLO | K31: TRUJILLO | L31: LA LIBERTAD | M31: Calle Francisco Bolognesi N° 561-Trujillo | N31: PRIVADO | O31: SUSANA DEL CARMEN ALARCON FERNANDEZ, | P31: salarconf@auna.pe | Q31: PATOLOGO CLINICO KAREN YANET CASTILLO MINAYA | R31: f | S31: - TM.GERALDINE HASTRID MONDRAGON GIL, TM. ANDERSON JESUS VIGO SALINAS, TM. KARLA GABRIELA FERNANDEZ SAAVEDRA | T31: 1 | U31: 0 | V31: 2 | W31: 2 | X31: N°2023-0148745, N°2023-0139194, N°2023-0164806 | Y31: HOSPITAL BELEN | AA31: TACNA | AB31: =COUNTIF($L$6:$L$601,AA31) -> 0
A32: 27 | B32: PER-BSIB60601-026 | C32: R.D. N° 154-2023 DIGDOT/MINSA | D32: 45166 | E32: 45173 | F32: 4981 | G32: II-1 | H32: DIRESA CAJAMARCA | I32: Hospital Santa María de Cutervo de Cajamarca | J32: CUTERVO | K32: CUTERVO | L32: CAJAMARCA | M32: Jr. Inca s/n | N32: MINSA | O32: ROSA DELGADO TORO | P32: oitesrscutervo@gmail.com | Q32: M.C. Victoria Vargas Vasquez | S32: Tecnólogos Médicos: Cristhy Carranza, Juan Collantes, Yamelly Coronel, Idelsa Flores. Bióloga Natali Zambrano | T32: 0 | U32: 1 | V32: 4 | W32: 1 | X32: N° 2023-0150368, 2023-0160492 | Y32: POR REGULARIZAR | AA32: UCAYALI | AB32: =COUNTIF($L$6:$L$601,AA32) -> 0
A33: 28 | B33: PER-BSIB150137-027 | C33: R.D. N° 163-2023 DIGDOT/MINSA | D33: 45184 | E33: 45201 | F33: 10434 | G33: II-E | H33: DIRIS LIMA ESTE | I33: HOSPITAL IIE SAN ISIDRO LABRADOR | J33: SANTA ANITA | K33: LIMA | L33: LIMA | M33: AVENIDA CARRETERA CENTRAL 1345 KM3,5 | N33: ESSALUD | O33: HECTOR BERASTAIN MERINO | P33: hector.berastain@essalud.gob.pe | Q33: Dra. SHIRLEY KAREM MORALES GUTIERREZ | S33: TM.SANTOS VARAS LENIN POLIVIO, TM.PERCY CRUZ ROSALES, TM.VICTOR HUGO LLAJA VERGARAY, TM.JAIME FELIX COCA NUÑEZ , TM.WILMER CRISENCIO GERI PAREDES | T33: 1 | U33: 0 | V33: 6 | W33: 0 | X33: N° 2023-0161980, 2023-0163842 y 2023-0172023 | Y33: POR REGULARIZAR | AA33: MOQUEGUA | AB33: =COUNTIF($L$6:$L$601,AA33) -> 0
A34: 29 | B34: PER-BSIB150103-028 | C34: R.D. N° 158-2023 DIGDOT/MINSA | D34: 45166 | E34: 45173 | F34: 8353 | G34: II-1 | H34: DIRIS LIMA ESTE | I34: HOSPITAL II VITARTE - ESSALUD | J34: ATE | K34: LIMA | L34: LIMA | M34: JR. SAN MARTIN DE PORRES N°265 | N34: ESSALUD | O34: JEAN LOUIS FRANCIA VELASQUEZ | P34: jean.francia@essalud.gob.pe | Q34: MEDICO PATOLOGO CLINICO IOHANA NAZARITA VERA NUÑEZ | S34: TM. SIMON EUGENIO ARHUATA CASAVILCA, TM JAIME ELIAS FLORENCIO FRETEL , TM HERMELINDA ROSA MONROY QUISPE, TM LUIS MIGUEL ZAMORA GONZALES | T34: 1 | U34: 0 | V34: 4 | W34: 0 | X34: N°2023-0171248, 2023-0174604 | Y34: POR REGULARIZAR | AA34: ANCASH | AB34: =COUNTIF($L$6:$L$601,AA34) -> 3
A35: 30 | B35: PER-BSIB120101-029 | C35: R.D. N° 165-2023 DIGDOT/MINSA | D35: 45184 | E35: 45201 | F35: 8858 | G35: II-2 | H35: DIRESA JUNIN | I35: RS: CLINICA ORTEGA SRL, NC: CLINICA ORTEGA | J35: HUANCAYO | K35: HUANCAYO | L35: JUNIN | M35: Avenida Daniel Alcides Carrión 1124 | N35: PRIVADO | O35: FELIX RAFAEL ORTEGA ALVAREZ | P35: gerencia.co@clinicaortega.pe, asistente.gerencia.dm@clinicaortega.pe | Q35: MEDICO PATOLOGO CLINICO CASTRO GERMANA LORENZO JOSE | R35: 964609360 | S35: TM.CONTRERAS ROMERO MONICA, VELIZ POMA MILAGRITOS, TELLO ENRIQUEZ TONY , PUMA PILCO , MARCOS COTERA SHYRLEY | T35: 1 | U35: 0 | V35: 5 | W35: 0 | X35: 2023-0153826, 2023-0166250, 2023-0182620 y 2023-0187216 | Y35: POR REGULARIZAR | AA35: AMAZONAS | AB35: =COUNTIF($L$6:$L$601,AA35) -> 0
A36: 31 | B36: PER-BSIB40126-030 | C36: R.D. N° 182-2023 DIGDOT/MINSA | D36: 45209 | E36: 45219 | F36: 13291 | G36: II-1 | H36: GERESA AREQUIPA | I36: HOSPITAL III YANAHUARA | J36: YANAHUARA | K36: AREQUIPA | L36: AREQUIPA | M36: Av. Zamacola S/N | N36: ESSALUD | O36: CARLOS CUYA MAMANI | P36: carlos.cuya@essalud.gob.pe | Q36: MARIA ALEJANDRA ALFARO MESTAS | R36: 992584622 | X36: N° 2023-0148320, N° 2023-0162412 | Y36: POR REGULARIZAR | AA36: TUMBES | AB36: =COUNTIF($L$6:$L$601,AA36) -> 1
A37: 32 | B37: PER-BSIB120401-031 | C37: R.D. N° 181-2023 DIGDOT/MINSA | D37: 45209 | E37: 45212 | F37: 365 | G37: II-1 | H37: DIRESA JUNIN | I37: Hospital Domingo Olavegoya, RS: Red de Salud Jauja | J37: JAUJA | K37: JAUJA | L37: JUNIN | M37: Jr. San Martin N°1153 Urb. Olavegoya | N37: MINSA | O37: MAGDIEL SALLY HUATUCO HUAMAN | P37: utesjauja@gmail.com | Q37: PATOLOGO MEDICO ZAPATA CALDERON ANA ROSARIO | R37: 9546655466 | S37: TM QUINTE GOMEZ ROSSY ROSITA CTMP13997, TM SOLIS CAMARENA LINDA ROSABEL CTMP12368, TM APACLLA NUÑEZ PATRICIA YOMAYRA CTMP12252 | T37: 1 | U37: 0 | V37: 3 | W37: 0 | X37: N°2023-0157758, N°2023-0170531, N°2023-0172509, N°2023-0173361, N°2023-0190344 | Y37: POR REGULARIZAR | AA37: PUNO | AB37: =COUNTIF($L$6:$L$601,AA37) -> 0
A38: 33 | B38: PER-BSIB120114-032 | C38: R.D. N° 186-2023 DIGDOT/MINSA | D38: 45219 | E38: 45224 | F38: 8024 | G38: II-1 | H38: DIRESA JUNIN | I38: CLINICA CAYETANO HEREDIA, RS: CLINICA CAYETANO HEREDIA S.A. | J38: EL TAMBO | K38: HUANCAYO | L38: JUNIN | M38: Avenida Huancavelica N°745 | N38: PRIVADO | O38: MARILUZ REGINA ALANIA FLORES (GG) | P38: laboratorio@clinicacayetanoheredia.com, deliss_14@hotmail.com | Q38: MEDICO PATOLOGO CLINICO ROLANDO TORRES ORUNA | R38: 947417007 | S38: TM FREDDY LEONEL CHAVEZ ALANIA, TM DANNA DELISA TERRAZOS ROMERO, TM KATHARINE MENDOZA AGUIRRE, TM JULIO PACHECO Y TM GIAN PIER MENDOZA SARAVIA | T38: 1 | U38: 0 | V38: 5 | W38: 0 | X38: N°2023-0164212, N°2023-0210993 | Y38: POR REGULARIZAR | AA38: MADRE DE DIOS | AB38: =COUNTIF($L$6:$L$601,AA38) -> 0
A39: 34 | B39: PER-BSIB130101-033 | C39: R.D. N° 192-2023 DIGDOT/MINSA | D39: 45219 | E39: 45224 | F39: 13373 | G39: II-1 | H39: GERESA LA LIBERTAD | I39: CLINICA PERUANO AMERICANA S.A. | J39: TRUJILLO | K39: TRUJILLO | L39: LA LIBERTAD | M39: Av. Mansiche N°810 | N39: PRIVADO | O39: JUAN MIGUEL DEXTRE AGREDA | P39: administración@clipam.com.pe | Q39: MEDICO PATOLOGO CATHERINE SAENZ PAREDES | R39: 961 000 913 | S39: Dra. Catherine Saenz Paredes, Blgo. Carlos Castillo Leon, TM. Eduardo Guerra Pachamango, Blgo. Carlos Rebaza Esquen, TM Veronica Agurto Zapata | T39: 1 | U39: 0 | V39: 2 | W39: 2 | X39: N° 2023-0200995 y 2023-0213878 | Y39: POR REGULARIZAR | AA39: APURIMAC | AB39: =COUNTIF($L$6:$L$601,AA39) -> 1
A40: 35 | B40: PER-BSIB140101-034 | C40: R.D. N° 199-2023 DIGDOT/MINSA | D40: 45232 | E40: 45236 | F40: 8151 | G40: II-E | H40: GERESA LAMBAYEQUE | I40: RS: HOSPITAL METROPOLITANO S.A, NC: CLINICA METROPOLITANA | J40: CHICLAYO | K40: CHICLAYO | L40: LAMBAYEQUE | M40: CALLE MANUEL MARIA IZAGA N°154 | N40: PRIVADO | O40: FERMIN FRANCISCO FALEN ESCAJADILLO | P40: dadministrativa@metrosac.com | Q40: MEDICO PATOLOGO JORGE LUIS GARCIA CARASSAS | R40: 957443724 DR. JAIME CARO GERENTE | S40: Lic.Luina Sánchez Contreras, Lic. María Rivas Castillo, Lic. Catherine Cantos Puicon,Lic. Liz Balcázar Chumacero | T40: 1 | U40: 0 | V40: 4 | W40: 0 | X40: N°2023-0171638 , N°2023-0218244 | Y40: POR REGULARIZAR | AA40: AYACUCHO | AB40: =COUNTIF($L$6:$L$601,AA40) -> 0
A41: 36 | B41: PER-BSIB150136-035 | C41: R.D. N° 203-2023 DIGDOT/MINSA | D41: 45244 | E41: 45250 | F41: 11401 | G41: II-2 | H41: DIRIS LIMA CENTRO | I41: RS: CENTRO MÉDICO CLÍNICA SAN JUDAS TADEO S.A.; NC: CLÍNICA SAN JUDAS TADEO | J41: SAN MIGUEL | K41: LIMA | L41: LIMA | M41: Calle Manuel Raygada N°170- Calle Laureano Martinez N° 140 | N41: PRIVADO | O41: Ricardo FIORANI RONDAN | Q41: MC PATOLOGO CLÍNICO CUBAS BANCES ZAHNDER - ACTUALIZADO 24/04/2024, SEGÚN CMSJT-0014-2024-DM CON EXP: 2024-0085036 | R41: 999074405 | T41: 1 | V41: 4 | X41: N° 2023-0192163, N° 2023-0200751, N° 2023-0205006, N° 2023-0220655, N° 2023-0223215, N° 2023-0224543 | Y41: POR REGULARIZAR | AA41: PASCO | AB41: =COUNTIF($L$6:$L$601,AA41) -> 0
A42: 37 | B42: PER-BSIB140106-036 | C42: R.D. N° 198-2023 DIGDOT/MINSA | D42: 45232 | E42: 45236 | F42: 10972 | G42: II-E | H42: GERESA LAMBAYEQUE | I42: Hospital Privado Juan Pablo II SAC | J42: LA VICTORIA | K42: CHICLAYO | L42: LAMBAYEQUE | M42: Av. Miguel Grau N°1461 | N42: PRIVADO | O42: MOISES ALEJANDRO ROSARIO BORREGO | P42: gerencia@hospitaljuanpablo.com | Q42: MC PATOLOGO JOSE LUIS GARCIA CARASAS | S42: Lic Morales Nuñez Olga y María Pisfil Chavez, Biologa Castañeda Moreno Isabel | T42: 1 | U42: 0 | V42: 2 | W42: 1 | X42: N° 2023-0180065 | Y42: POR REGULARIZAR | AB42: =SUM(AB15:AB41) -> 81
A43: 38 | B43: PER-BSIB150133-037 | C43: R.D. N° 204-2023 DIGDOT/MINSA | D43: 45257 | E43: 45265 | F43: 18985 | G43: II-2 | H43: DIRIS LIMA SUR | I43: R.S:CLINICA SANTA MARTHA DEL SUR SOCIEDAD ANONIMA CERRADA; NC:CLINICA SANTA MARTHA DE SUR | J43: SAN JUAN DE MIRAFLORES | K43: LIMA | M43: AV BELISARIO SUAREX N°998 | N43: PRIVADO | O43: ENNID SARITA CHIOK RIVADENEYRA | P43: echiok@sanpablo.com.pe | Q43: MEDICO PATOLOGO : TATIANA SARAVIA ROMANI | R43: 937677826 | S43: Lic. Aviles Balarezo Yessenia; Lic.lopez Morillo yrbelis; Nuñez Lazo Luis Alberto; Fihueras Quijada Laura | T43: 1 | U43: 0 | V43: 4 | W43: 0 | X43: N° 2023-0188926, 2023-0205681, 2023-0226343 | Y43: POR REGULARIZAR
...

Sheet BS I C
A1: angamos
A4: BANCO DE SANGRE TIPO I C
A5: N° | B5: N° DE INSCRIPCIÓN | C5: ACTO RESOLUTIVO | D5: FECHA (DIA/MES/AÑO) | E5: FECHA DE PUBLICACION RD | F5: RENIPRESS | G5: IPRESS | H5: DIRIS/DIRESA | I5: IPRESS | J5: DISTRITO | K5: PROVINCIA | L5: REGION | M5: REGION | N5: SUBSECTOR | O5: DIRECTOR | P5: CONTACTO | Q5: JEFE DE BANCO DE SANGRE | R5: CONTACTO | S5: PERSONAL | T5: Patólogo Clínico | U5: Otra Especial | V5: T.M. | W5: Biól. | X5: N° EXPEDIENTE | Y5: CONVENIO | AA5: PRIVADO | AB5: =COUNTIF(N6:N599,"PRIVADO") -> 7
A6: 1 | B6: PER-BSIC150122-001 | C6: R.D. N° 006-2023 DIGDOT/MINSA | D6: 44938 | E6: 44953 | F6: 8489 | G6: II-2 | H6: DIRIS LIMA CENTRO | I6: ESSALUD-HOSPITAL III SUAREZ ANGAMOS | J6: MIRAFLORES | K6: LIMA | L6: LIMA | M6: AV ANGAMOS ESTE N°261 | N6: ESSALUD | O6: DR.FAUSTO ANIBAL VILLAVICENCIO SILVA | P6: 980234828 / fausto.villavicencio@essalud.gob.pe | Q6: DRA KATTIA ANAHI RIVERO VILLEGAS | R6: 980234828 | S6: DRA ROCIO ALVAREZ MATAMOROS, DRA MARIZA RAMOS GARCIA, LIC ANALIA MERCEDES CORREA SANTILLAN, LIC ERIKA ROJAS MONZON, LIC MANSUETO CAJALEON LLANOS, LIC JOHN ANTONIO COLQUI REINOSO, LIC MARTHA CALDERON LOZANO, LIC ROSA GOMERO BLAS, LIC ERIKA LARA PACHERRES, LIC GLADYS QUISPE PALMA, LIC LIZ ALVARADO PEZO | T6: 2 | U6: 0 | V6: 20 | W6: 0 | X6: 2022-0112748 - 022-0114514 | Y6: POR REGULARIZAR | AA6: MINSA | AB6: =COUNTIF(N6:N600,"MINSA") -> 6
